2021-10-22 16:21:48.909 [error] <0.333.0> Supervisor 'Elixir.TseApi.Supervisor' had child 'Elixir.TSE.Consumer' started with 'Elixir.TSE.Consumer':start_link([]) at undefined exit with reason {'EXIT',{undef,[{'Elixir.TSE.Consumer',start_link,[[]],[]},{supervisor,do_start_child_i,3,[{file,"supervisor.erl"},{line,379}]},{supervisor,do_start_child,2,[{file,"supervisor.erl"},{line,365}]},{supervisor,'-start_children/2-fun-0-',3,[{file,"supervisor.erl"},{line,349}]},{supervisor,children_map,4,[{file,"supervisor.erl"},{line,1157}]},{supervisor,init_children,2,[{file,"supervisor.erl"},{line,315}]},{gen_server,init_it,2,[{file,"gen_server.erl"},{line,374}]},{gen_server,init_it,6,[{file,...},...]}]}} in context start_error
2021-10-22 16:21:48.909 [error] <0.331.0> CRASH REPORT Process <0.331.0> with 0 neighbours exited with reason: {{shutdown,{failed_to_start_child,'Elixir.TSE.Consumer',{'EXIT',{undef,[{'Elixir.TSE.Consumer',start_link,[[]],[]},{supervisor,do_start_child_i,3,[{file,"supervisor.erl"},{line,379}]},{supervisor,do_start_child,2,[{file,"supervisor.erl"},{line,365}]},{supervisor,'-start_children/2-fun-0-',3,[{file,"supervisor.erl"},{line,349}]},{supervisor,children_map,4,[{file,"supervisor.erl"},{line,1157}]},{supervisor,init_children,2,[{file,"supervisor.erl"},{line,315}]},{gen_server,init_it,2,[{file,"ge..."},...]},...]}}}},...} in application_master:init/4 line 138
2021-10-22 16:23:33.146 [error] <0.324.0> CRASH REPORT Process <0.324.0> with 0 neighbours exited with reason: #{'__exception__' => true,'__struct__' => 'Elixir.ArgumentError',message => <<"supervisors expect each child to be one of the following:\n\n  * a module\n  * a {module, arg} tuple\n  * a child specification as a map with at least the :id and :start fields\n  * or a tuple with 6 elements generated by Supervisor.Spec (deprecated)\n\nGot: {TSE.Consumer}\n">>} in 'Elixir.Supervisor':init_child/1 line 648 in application_master:init/4 line 138
2021-10-22 16:25:48.917 [error] <0.332.0>@Elixir.TSE.Consumer:setup_exchange:41 Supervisor 'Elixir.TseApi.Supervisor' had child 'Elixir.TSE.Consumer' started with 'Elixir.TSE.Consumer':start_link([]) at undefined exit with reason no match of right hand value {ok,#{consumer_count => 0,message_count => 0,queue => <<"chung_khoan_co_so_queue">>}} in 'Elixir.TSE.Consumer':setup_exchange/1 line 41 in context start_error
2021-10-22 16:25:48.917 [error] <0.351.0>@Elixir.TSE.Consumer:setup_exchange:41 CRASH REPORT Process <0.351.0> with 0 neighbours crashed with reason: no match of right hand value {ok,#{consumer_count => 0,message_count => 0,queue => <<"chung_khoan_co_so_queue">>}} in 'Elixir.TSE.Consumer':setup_exchange/1 line 41
2021-10-22 16:25:48.917 [error] <0.330.0> CRASH REPORT Process <0.330.0> with 0 neighbours exited with reason: {{shutdown,{failed_to_start_child,'Elixir.TSE.Consumer',{{badmatch,{ok,#{consumer_count => 0,message_count => 0,queue => <<"chung_khoan_co_so_queue">>}}},[{'Elixir.TSE.Consumer',setup_exchange,1,[{file,"lib/tse_api/consumer.ex"},{line,41}]},{'Elixir.TSE.Consumer',init,1,[{file,"lib/tse_api/consumer.ex"},{line,16}]},{gen_server,init_it,2,[{file,"gen_server.erl"},{line,374}]},{gen_server,init_it,6,[{file,"gen_server.erl"},{line,342}]},{proc_lib,init_p_do_apply,3,[{file,"proc_lib.erl"},{line,249}]}]}}},...} in application_master:init/4 line 138
2021-10-22 16:29:58.587 [error] <0.327.0> Supervisor 'Elixir.TseApi.Supervisor' had child 'Elixir.TSE.Consumer' started with 'Elixir.TSE.Consumer':start_link([]) at undefined exit with reason {{shutdown,{server_initiated_close,406,<<"PRECONDITION_FAILED - inequivalent arg 'type' for exchange 'tse_exchange' in vhost 'fffdmiik': received 'fanout' but current is 'direct'">>}},{gen_server,call,[<0.365.0>,{call,{'exchange.declare',0,<<"tse_exchange">>,<<"fanout">>,false,true,false,false,false,[]},none,<0.346.0>},70000]}} in context start_error
2021-10-22 16:29:58.587 [error] <0.346.0> CRASH REPORT Process <0.346.0> with 0 neighbours exited with reason: {{shutdown,{server_initiated_close,406,<<"PRECONDITION_FAILED - inequivalent arg 'type' for exchange 'tse_exchange' in vhost 'fffdmiik': received 'fanout' but current is 'direct'">>}},{gen_server,call,[<0.365.0>,{call,{'exchange.declare',0,<<"tse_exchange">>,<<"fanout">>,false,true,false,false,false,[]},none,<0.346.0>},70000]}} in gen_server:call/3 line 223
2021-10-22 16:29:58.587 [error] <0.325.0> CRASH REPORT Process <0.325.0> with 0 neighbours exited with reason: {{shutdown,{failed_to_start_child,'Elixir.TSE.Consumer',{{shutdown,{server_initiated_close,406,<<"PRECONDITION_FAILED - inequivalent arg 'type' for exchange 'tse_exchange' in vhost 'fffdmiik': received 'fanout' but current is 'direct'">>}},{gen_server,call,[<0.365.0>,{call,{'exchange.declare',0,<<"tse_exchange">>,<<"fanout">>,false,true,false,false,false,[]},none,<0.346.0>},70000]}}}},{'Elixir.TseApi.Application',start,[normal,[]]}} in application_master:init/4 line 138
2021-10-22 16:41:10.346 [error] <0.346.0> CRASH REPORT Process <0.346.0> with 0 neighbours exited with reason: {{shutdown,{server_initiated_close,406,<<"PRECONDITION_FAILED - inequivalent arg 'type' for exchange 'tse_exchange' in vhost 'fffdmiik': received 'fanout' but current is 'direct'">>}},{gen_server,call,[<0.365.0>,{call,{'exchange.declare',0,<<"tse_exchange">>,<<"fanout">>,false,true,false,false,false,[]},none,<0.346.0>},70000]}} in gen_server:call/3 line 223
2021-10-22 16:41:10.346 [error] <0.327.0> Supervisor 'Elixir.TseApi.Supervisor' had child 'Elixir.TSE.Consumer' started with 'Elixir.TSE.Consumer':start_link([]) at undefined exit with reason {{shutdown,{server_initiated_close,406,<<"PRECONDITION_FAILED - inequivalent arg 'type' for exchange 'tse_exchange' in vhost 'fffdmiik': received 'fanout' but current is 'direct'">>}},{gen_server,call,[<0.365.0>,{call,{'exchange.declare',0,<<"tse_exchange">>,<<"fanout">>,false,true,false,false,false,[]},none,<0.346.0>},70000]}} in context start_error
2021-10-22 16:41:10.362 [error] <0.325.0> CRASH REPORT Process <0.325.0> with 0 neighbours exited with reason: {{shutdown,{failed_to_start_child,'Elixir.TSE.Consumer',{{shutdown,{server_initiated_close,406,<<"PRECONDITION_FAILED - inequivalent arg 'type' for exchange 'tse_exchange' in vhost 'fffdmiik': received 'fanout' but current is 'direct'">>}},{gen_server,call,[<0.365.0>,{call,{'exchange.declare',0,<<"tse_exchange">>,<<"fanout">>,false,true,false,false,false,[]},none,<0.346.0>},70000]}}}},{'Elixir.TseApi.Application',start,[normal,[]]}} in application_master:init/4 line 138
2021-10-22 16:44:02.076 [error] <0.327.0> Supervisor 'Elixir.TseApi.Supervisor' had child 'Elixir.TSE.Consumer' started with 'Elixir.TSE.Consumer':start_link([]) at undefined exit with reason {{shutdown,{server_initiated_close,406,<<"PRECONDITION_FAILED - inequivalent arg 'type' for exchange 'tse_exchange' in vhost 'fffdmiik': received 'fanout' but current is 'direct'">>}},{gen_server,call,[<0.365.0>,{call,{'exchange.declare',0,<<"tse_exchange">>,<<"fanout">>,false,false,false,false,false,[]},none,<0.346.0>},70000]}} in context start_error
2021-10-22 16:44:02.077 [error] <0.346.0> CRASH REPORT Process <0.346.0> with 0 neighbours exited with reason: {{shutdown,{server_initiated_close,406,<<"PRECONDITION_FAILED - inequivalent arg 'type' for exchange 'tse_exchange' in vhost 'fffdmiik': received 'fanout' but current is 'direct'">>}},{gen_server,call,[<0.365.0>,{call,{'exchange.declare',0,<<"tse_exchange">>,<<"fanout">>,false,false,false,false,false,[]},none,<0.346.0>},70000]}} in gen_server:call/3 line 223
2021-10-22 16:44:02.078 [error] <0.325.0> CRASH REPORT Process <0.325.0> with 0 neighbours exited with reason: {{shutdown,{failed_to_start_child,'Elixir.TSE.Consumer',{{shutdown,{server_initiated_close,406,<<"PRECONDITION_FAILED - inequivalent arg 'type' for exchange 'tse_exchange' in vhost 'fffdmiik': received 'fanout' but current is 'direct'">>}},{gen_server,call,[<0.365.0>,{call,{'exchange.declare',0,<<"tse_exchange">>,<<"fanout">>,false,false,false,false,false,[]},none,<0.346.0>},70000]}}}},{'Elixir.TseApi.Application',start,[normal,[]]}} in application_master:init/4 line 138
2021-10-22 16:46:56.608 [error] <0.327.0> Supervisor 'Elixir.TseApi.Supervisor' had child 'Elixir.TSE.Consumer' started with 'Elixir.TSE.Consumer':start_link([]) at undefined exit with reason {{shutdown,{server_initiated_close,406,<<"PRECONDITION_FAILED - inequivalent arg 'type' for exchange 'tse_exchange' in vhost 'fffdmiik': received 'fanout' but current is 'direct'">>}},{gen_server,call,[<0.365.0>,{call,{'exchange.declare',0,<<"tse_exchange">>,<<"fanout">>,false,false,false,false,false,[]},none,<0.346.0>},70000]}} in context start_error
2021-10-22 16:46:56.608 [error] <0.346.0> CRASH REPORT Process <0.346.0> with 0 neighbours exited with reason: {{shutdown,{server_initiated_close,406,<<"PRECONDITION_FAILED - inequivalent arg 'type' for exchange 'tse_exchange' in vhost 'fffdmiik': received 'fanout' but current is 'direct'">>}},{gen_server,call,[<0.365.0>,{call,{'exchange.declare',0,<<"tse_exchange">>,<<"fanout">>,false,false,false,false,false,[]},none,<0.346.0>},70000]}} in gen_server:call/3 line 223
2021-10-22 16:46:56.608 [error] <0.325.0> CRASH REPORT Process <0.325.0> with 0 neighbours exited with reason: {{shutdown,{failed_to_start_child,'Elixir.TSE.Consumer',{{shutdown,{server_initiated_close,406,<<"PRECONDITION_FAILED - inequivalent arg 'type' for exchange 'tse_exchange' in vhost 'fffdmiik': received 'fanout' but current is 'direct'">>}},{gen_server,call,[<0.365.0>,{call,{'exchange.declare',0,<<"tse_exchange">>,<<"fanout">>,false,false,false,false,false,[]},none,<0.346.0>},70000]}}}},{'Elixir.TseApi.Application',start,[normal,[]]}} in application_master:init/4 line 138
2021-10-22 16:47:55.727 [error] <0.346.0> CRASH REPORT Process <0.346.0> with 0 neighbours exited with reason: {{shutdown,{server_initiated_close,406,<<"PRECONDITION_FAILED - inequivalent arg 'type' for exchange 'tse_exchange' in vhost 'fffdmiik': received 'fanout' but current is 'direct'">>}},{gen_server,call,[<0.365.0>,{call,{'exchange.declare',0,<<"tse_exchange">>,<<"fanout">>,false,false,false,false,false,[]},none,<0.346.0>},70000]}} in gen_server:call/3 line 223
2021-10-22 16:47:55.727 [error] <0.327.0> Supervisor 'Elixir.TseApi.Supervisor' had child 'Elixir.TSE.Consumer' started with 'Elixir.TSE.Consumer':start_link([]) at undefined exit with reason {{shutdown,{server_initiated_close,406,<<"PRECONDITION_FAILED - inequivalent arg 'type' for exchange 'tse_exchange' in vhost 'fffdmiik': received 'fanout' but current is 'direct'">>}},{gen_server,call,[<0.365.0>,{call,{'exchange.declare',0,<<"tse_exchange">>,<<"fanout">>,false,false,false,false,false,[]},none,<0.346.0>},70000]}} in context start_error
2021-10-22 16:47:55.727 [error] <0.325.0> CRASH REPORT Process <0.325.0> with 0 neighbours exited with reason: {{shutdown,{failed_to_start_child,'Elixir.TSE.Consumer',{{shutdown,{server_initiated_close,406,<<"PRECONDITION_FAILED - inequivalent arg 'type' for exchange 'tse_exchange' in vhost 'fffdmiik': received 'fanout' but current is 'direct'">>}},{gen_server,call,[<0.365.0>,{call,{'exchange.declare',0,<<"tse_exchange">>,<<"fanout">>,false,false,false,false,false,[]},none,<0.346.0>},70000]}}}},{'Elixir.TseApi.Application',start,[normal,[]]}} in application_master:init/4 line 138
2021-10-22 16:51:45.292 [error] <0.346.0> CRASH REPORT Process <0.346.0> with 0 neighbours exited with reason: {{shutdown,{server_initiated_close,406,<<"PRECONDITION_FAILED - inequivalent arg 'type' for exchange 'tse_exchange' in vhost 'fffdmiik': received 'fanout' but current is 'direct'">>}},{gen_server,call,[<0.365.0>,{call,{'exchange.declare',0,<<"tse_exchange">>,<<"fanout">>,false,true,false,false,false,[]},none,<0.346.0>},70000]}} in gen_server:call/3 line 223
2021-10-22 16:51:45.292 [error] <0.327.0> Supervisor 'Elixir.TseApi.Supervisor' had child 'Elixir.TSE.Consumer' started with 'Elixir.TSE.Consumer':start_link([]) at undefined exit with reason {{shutdown,{server_initiated_close,406,<<"PRECONDITION_FAILED - inequivalent arg 'type' for exchange 'tse_exchange' in vhost 'fffdmiik': received 'fanout' but current is 'direct'">>}},{gen_server,call,[<0.365.0>,{call,{'exchange.declare',0,<<"tse_exchange">>,<<"fanout">>,false,true,false,false,false,[]},none,<0.346.0>},70000]}} in context start_error
2021-10-22 16:51:45.292 [error] <0.325.0> CRASH REPORT Process <0.325.0> with 0 neighbours exited with reason: {{shutdown,{failed_to_start_child,'Elixir.TSE.Consumer',{{shutdown,{server_initiated_close,406,<<"PRECONDITION_FAILED - inequivalent arg 'type' for exchange 'tse_exchange' in vhost 'fffdmiik': received 'fanout' but current is 'direct'">>}},{gen_server,call,[<0.365.0>,{call,{'exchange.declare',0,<<"tse_exchange">>,<<"fanout">>,false,true,false,false,false,[]},none,<0.346.0>},70000]}}}},{'Elixir.TseApi.Application',start,[normal,[]]}} in application_master:init/4 line 138
2021-10-22 16:54:20.459 [error] <0.346.0> CRASH REPORT Process <0.346.0> with 0 neighbours exited with reason: {{shutdown,{server_initiated_close,406,<<"PRECONDITION_FAILED - inequivalent arg 'type' for exchange 'tse_exchange' in vhost 'fffdmiik': received 'fanout' but current is 'direct'">>}},{gen_server,call,[<0.365.0>,{call,{'exchange.declare',0,<<"tse_exchange">>,<<"fanout">>,false,false,false,false,false,[]},none,<0.346.0>},70000]}} in gen_server:call/3 line 223
2021-10-22 16:54:20.459 [error] <0.327.0> Supervisor 'Elixir.TseApi.Supervisor' had child 'Elixir.TSE.Consumer' started with 'Elixir.TSE.Consumer':start_link([]) at undefined exit with reason {{shutdown,{server_initiated_close,406,<<"PRECONDITION_FAILED - inequivalent arg 'type' for exchange 'tse_exchange' in vhost 'fffdmiik': received 'fanout' but current is 'direct'">>}},{gen_server,call,[<0.365.0>,{call,{'exchange.declare',0,<<"tse_exchange">>,<<"fanout">>,false,false,false,false,false,[]},none,<0.346.0>},70000]}} in context start_error
2021-10-22 16:54:20.459 [error] <0.325.0> CRASH REPORT Process <0.325.0> with 0 neighbours exited with reason: {{shutdown,{failed_to_start_child,'Elixir.TSE.Consumer',{{shutdown,{server_initiated_close,406,<<"PRECONDITION_FAILED - inequivalent arg 'type' for exchange 'tse_exchange' in vhost 'fffdmiik': received 'fanout' but current is 'direct'">>}},{gen_server,call,[<0.365.0>,{call,{'exchange.declare',0,<<"tse_exchange">>,<<"fanout">>,false,false,false,false,false,[]},none,<0.346.0>},70000]}}}},{'Elixir.TseApi.Application',start,[normal,[]]}} in application_master:init/4 line 138
2021-10-22 16:56:26.769 [error] <0.327.0> Supervisor 'Elixir.TseApi.Supervisor' had child 'Elixir.TSE.Consumer' started with 'Elixir.TSE.Consumer':start_link([]) at undefined exit with reason {'EXIT',{undef,[{'Elixir.TSE.Consumer',start_link,[[]],[]},{supervisor,do_start_child_i,3,[{file,"supervisor.erl"},{line,379}]},{supervisor,do_start_child,2,[{file,"supervisor.erl"},{line,365}]},{supervisor,'-start_children/2-fun-0-',3,[{file,"supervisor.erl"},{line,349}]},{supervisor,children_map,4,[{file,"supervisor.erl"},{line,1157}]},{supervisor,init_children,2,[{file,"supervisor.erl"},{line,315}]},{gen_server,init_it,2,[{file,"gen_server.erl"},{line,374}]},{gen_server,init_it,6,[{file,...},...]}]}} in context start_error
2021-10-22 16:56:26.769 [error] <0.325.0> CRASH REPORT Process <0.325.0> with 0 neighbours exited with reason: {{shutdown,{failed_to_start_child,'Elixir.TSE.Consumer',{'EXIT',{undef,[{'Elixir.TSE.Consumer',start_link,[[]],[]},{supervisor,do_start_child_i,3,[{file,"supervisor.erl"},{line,379}]},{supervisor,do_start_child,2,[{file,"supervisor.erl"},{line,365}]},{supervisor,'-start_children/2-fun-0-',3,[{file,"supervisor.erl"},{line,349}]},{supervisor,children_map,4,[{file,"supervisor.erl"},{line,1157}]},{supervisor,init_children,2,[{file,"supervisor.erl"},{line,315}]},{gen_server,init_it,2,[{file,"ge..."},...]},...]}}}},...} in application_master:init/4 line 138
